# Issues Analysis Report

## Critical Issue: 'AsyncResult' object has no attribute 'apply_async'

### Root Cause
The error occurs in the `generate_collection_embeddings_simple` task when it tries to call `apply_async()` on `completion_callback_signature`, but the parameter is receiving an `AsyncResult` object instead of a Celery signature.

### Location
- **File**: `src/fileintel/tasks/workflow_tasks.py`
- **Method**: `generate_collection_embeddings_simple`
- **Lines**: 238 and 272

### Detailed Analysis

#### Problem Context
```python
# Line 84: Creates a proper Celery signature
completion_callback = mark_collection_completed.s(collection_id)

# Line 92: Passes signature as parameter
completion_callback_signature=completion_callback,

# Lines 238, 272: ERROR - tries to call apply_async on wrong object type
completion_result = completion_callback_signature.apply_async(
    args=[document_results]
).get()
```

#### The Issue
When `completion_callback` is created using `mark_collection_completed.s(collection_id)`, it correctly creates a Celery signature object. However, somewhere in the workflow orchestration, this signature is being converted to an `AsyncResult` object, which doesn't have an `apply_async()` method.

### Related Methods and Imports

#### Method Chain
1. **`complete_collection_analysis`** (line 22-137) - Main orchestration method
   - Creates `completion_callback = mark_collection_completed.s(collection_id)` (line 84)
   - Passes it to `generate_collection_embeddings_simple.s()` (line 92)

2. **`generate_collection_embeddings_simple`** (line 206-320) - Where error occurs
   - Receives `completion_callback_signature` parameter (line 207)
   - Tries to call `completion_callback_signature.apply_async()` (lines 238, 272)

3. **`mark_collection_completed`** (line 140-202) - Target callback method
   - Should be called by the signature

#### Related Imports
```python
from celery import group, chain, chord, signature  # Line 10
from fileintel.celery_config import app  # Line 12
from .base import BaseFileIntelTask  # Line 13
```

#### Functions that use the problematic method
- `complete_collection_analysis` - Creates and passes the signature
- `generate_collection_embeddings_simple` - Uses the signature incorrectly

### Error Log Context
```
[2025-09-28 10:54:20,622: ERROR/ForkPoolWorker-1] Error in complete collection analysis: 'AsyncResult' object has no attribute 'apply_async'
[2025-09-28 10:54:20,640: INFO/ForkPoolWorker-1] Updated collection 05dcb4da-c518-40b8-8e9b-7786a8c89c99 status to failed
```

### Potential Root Causes

1. **Parameter Type Confusion**: The `completion_callback_signature` parameter might be receiving an `AsyncResult` from the Celery workflow orchestration instead of the expected signature.

2. **Celery Chord/Group Behavior**: When using complex Celery patterns (chord, group), the callback signatures might be automatically executed and their results (AsyncResult objects) passed instead of the signatures themselves.

3. **Workflow Orchestration Issue**: The chord pattern at line 89-94 might be causing the signature to be executed prematurely, converting it to an AsyncResult.

### Recommended Fixes

1. **Type Check and Convert**: Add type checking to detect AsyncResult and handle it appropriately
2. **Signature Recreation**: If receiving AsyncResult, recreate the signature from the original task
3. **Workflow Pattern Refactor**: Simplify the chord pattern to avoid signature/result confusion
4. **Direct Task Call**: Instead of using `apply_async()`, call the task directly if already dealing with results

### Impact
- Collection processing fails completely
- Documents are processed but embedding generation and completion callbacks fail
- Collections are marked as "failed" status instead of "completed"
- Workflow orchestration is broken for any collection that uses embedding generation

### Files Modified in Recent Commits
- `src/fileintel/api/routes/collections_v2.py` - API layer calling the workflows
- `src/fileintel/storage/models.py` - Data models
- `src/fileintel/storage/vector_search_storage.py` - Storage layer
- `debug_vector_search.py` - Debug script (new file)

The issue appears to be in the workflow orchestration logic rather than the recent changes to storage or API layers.

---

## Issue 2: PostgreSQL Vector Operator Error

### Root Cause
PostgreSQL is missing the pgvector extension or the extension is not properly installed/enabled, causing the `<=>` vector distance operator to be undefined.

### Location
- **File**: `src/fileintel/storage/vector_search_storage.py`
- **Method**: `find_relevant_chunks_in_collection`
- **Lines**: 79, 84, 86

### Error Details
```
(psycopg2.errors.UndefinedFunction) operator does not exist: vector <=> numeric[]
LINE 10: 1 - (c.embedding <=> ARRAY[0.01816732...
HINT: No operator matches the given name and argument types. You might need to add explicit type casts.
```

### Related Methods and Functions
- `find_relevant_chunks_in_collection` - Main method using vector similarity search
- `find_relevant_chunks_in_document` - Similar vector search for documents
- `find_relevant_chunks_hybrid` - Hybrid search using vector operations

### Impact
- Vector similarity search completely broken
- Query operations fail when trying to find relevant chunks
- Collections cannot be queried for content

---

## Issue 3: GraphRAG Settings Configuration Error

### Root Cause
The Settings configuration has been refactored to consolidate GraphRAG settings into the RAG settings section, but some code still tries to access `settings.graphrag` instead of the new structure.

### Location
- **Files**: Multiple files in `src/fileintel/rag/graph_rag/`
- **Error**: `'Settings' object has no attribute 'graphrag'`

### Configuration Structure Change
**Old structure** (still being accessed by some code):
```python
settings.graphrag.llm_model
settings.graphrag.embedding_model
settings.graphrag.cache.enabled
```

**New structure** (in config.py):
```python
settings.rag.llm_model
settings.rag.embedding_model
settings.rag.cache.enabled
```

### Related Files and Methods
- `src/fileintel/rag/graph_rag/adapters/config_adapter.py` - Lines 52, 55, 143, 150, 159, 166, 219, 223
- `src/fileintel/rag/graph_rag/services/dataframe_cache.py` - Lines 23, 26, 29, 92, 101
- `src/fileintel/rag/graph_rag/services/parquet_loader.py` - Line 44

### Impact
- GraphRAG indexing operations fail
- GraphRAG status requests return 500 errors
- Any GraphRAG functionality is broken

---

## Issue 4: API Response Validation Error

### Root Cause
The `ApiResponseV2` model expects a `timestamp` field but the GraphRAG status endpoint is not providing it, causing Pydantic validation to fail.

### Location
- **File**: `src/fileintel/api/routes/graphrag_v2.py`
- **Method**: `get_graphrag_system_status`
- **Line**: 352-354

### Error Details
```
1 validation error for ApiResponseV2
timestamp
  Field required [type=missing, input_value={'success': True, 'messag...'community_detection']}}, input_type=dict]
```

### Related Methods
- `get_graphrag_system_status` - Returns status without timestamp
- `ApiResponseV2` model - Requires timestamp field

### Impact
- GraphRAG system status endpoint returns 500 errors
- API responses fail validation
- Frontend/CLI cannot get GraphRAG system status

---

## Issue 5: Vector Search Query Execution Confirmed Broken

### Root Cause
This confirms **Issue 2** - the PostgreSQL pgvector extension is not properly installed or enabled, causing all vector similarity searches to fail at the database level.

### Location
- **File**: `src/fileintel/storage/vector_search_storage.py`
- **Method**: `find_relevant_chunks_in_collection`
- **Lines**: 79, 84, 86

### Error Context
The error occurs during a successful query flow:
1. ✅ Embedding provider successfully generates query embedding
2. ✅ Collection exists and is found
3. ❌ **PostgreSQL vector operator fails** when executing similarity search
4. ✅ API still returns 200 OK (but with empty/failed results)

### Detailed Error
```
(psycopg2.errors.UndefinedFunction) operator does not exist: vector <=> numeric[]
LINE 10: 1 - (c.embedding <=> ARRAY[0.01955970004...
HINT: No operator matches the given name and argument types. You might need to add explicit type casts.
```

### SQL Query That Fails
```sql
SELECT
    c.id as chunk_id,
    c.chunk_text,
    c.position,
    c.chunk_metadata,
    d.filename,
    d.original_filename,
    d.id as document_id,
    1 - (c.embedding <=> %(query_embedding)s) as similarity
FROM document_chunks c
JOIN documents d ON c.document_id = d.id
WHERE d.collection_id = %(collection_id)s
    AND c.embedding IS NOT NULL
    AND 1 - (c.embedding <=> %(query_embedding)s) >= %(similarity_threshold)s
ORDER BY c.embedding <=> %(query_embedding)s
LIMIT %(limit)s
```

### Related Components Working Correctly
- ✅ Embedding generation (vLLM server responding)
- ✅ API routing and validation
- ✅ Collection lookup
- ✅ Database connection

### Database Requirements
The issue requires installing/enabling pgvector extension:
```sql
CREATE EXTENSION IF NOT EXISTS vector;
```

### Impact
- **All vector similarity searches fail**
- **Primary RAG functionality broken**
- Query commands return empty results instead of similar chunks
- Users cannot get semantic search results from their collections
- Vector-based document analysis completely non-functional